Workbook
Name A10000000: #REF!
Name A100000000: #REF!
Name A10000099: #REF!
Name A10000100: #REF!
Name A10000499: #REF!
Name A10000500: #REF!
Name A10000999: #REF!
Name A1050000: #REF!
Name A1100000: #REF!
Name A11000000: #REF!
Name A1405200170: #REF!
Name A1542524: #REF!
Name A1999999: #REF!
Name A50000000: #REF!

Sheet PRONTA ENTREGA TOTAL
B1: c | O1: =_xlfn.XLOOKUP($A1,#REF!,#REF!,"",0) -> #REF! | P1: =_xlfn.XLOOKUP($A1,#REF!,#REF!,"",0) -> #REF! | Q1: =_xlfn.XLOOKUP($A1,#REF!,#REF!,"",0) -> #REF! | R1: =_xlfn.XLOOKUP($A1,#REF!,#REF!,"",0) -> #REF! | Z1: ATUALIZADO EM: | AA1: 45962
A2: Cod.Movelsoft | B2: - | C2: MARCA | D2: DESCRIÇÃO DO PRODUTO | E2: COMPRIMENTO | F2: LARGURA | G2: ALTURA | H2: DIAMETRO | I2: DE | J2: DESCONTO | K2: POR | L2: MODULARES | M2: Cod.Movelsoft2 | N2: CODIGO DO PRODUTO | O2: LOJA TEODORO | P2: LOJA LAR CENTER | Q2: LOJA D&D | R2: LOJA GABRIEL | S2: ESTOQUE 8000 | T2: ESTOQUE DISPONIVEL | U2: LINK_IMAGEM | V2: IMAGEM
A3: 270745 | B3: =IFERROR((VLOOKUP(A3,'[1]LISTA ETIQUETAS'!O:X,3,0)),"PRODUTO SEM ESTOQUE") -> EST BUFFET BENJAMIN (FREIJO LAVADO) | C3: =VLOOKUP(A3,'[1]LISTA ETIQUETAS'!$O:$BT,58,0) -> DPOT BUFFET | D3: =VLOOKUP(A3,'[1]LISTA ETIQUETAS'!$O:$BU,59,0) -> BUFFET BENJAMIN | E3: =IF(VLOOKUP(A3,'[1]LISTA ETIQUETAS'!O:W,4,0)="",(VLOOKUP(A3,'[1]LISTA ETIQUETAS'!O:W,7,0)),(VLOOKUP(A3,'[1]LISTA ETIQUETAS'!O:W,4,0))) -> 2.4 | F3: =IF(VLOOKUP(A3,'[1]LISTA ETIQUETAS'!O:W,5,0)="",(VLOOKUP(A3,'[1]LISTA ETIQUETAS'!O:W,8,0)),(VLOOKUP(A3,'[1]LISTA ETIQUETAS'!O:W,5,0))) -> 0.5 | G3: =IF(VLOOKUP(A3,'[1]LISTA ETIQUETAS'!O:W,6,0)="",(VLOOKUP(A3,'[1]LISTA ETIQUETAS'!O:W,9,0)),(VLOOKUP(A3,'[1]LISTA ETIQUETAS'!O:W,5,0))) -> 0.75 | H3: =IFERROR((VLOOKUP(A3,'[1]LISTA ETIQUETAS'!O:X,10,0)),"") -> 0 | I3: =IFERROR((VLOOKUP(A3,'[1]LISTA ETIQUETAS'!O:Z,12,0)),"") -> 0 | J3: =VLOOKUP(A3,'[1]LISTA ETIQUETAS'!$O:$AA,13,0) -> 0.5 | K3: =IFERROR(I3-I3*J3,"") -> 0 | L3: =IF(VLOOKUP(A3,'[1]LISTA ETIQUETAS'!O:AC,15,0)="","",(VLOOKUP(A3,'[1]LISTA ETIQUETAS'!O:AC,15,0))) | M3: =VLOOKUP(A3,'[1]LISTA ETIQUETAS'!$O:$BS,57,0) -> 0 | N3: =IF(M3=0,A3,M3) -> 270745 | S3: =_xlfn.XLOOKUP($A3,'[1]LISTA ETIQUETAS'!$O:$O,'[1]LISTA ETIQUETAS'!H:H,"",0) -> 1 | T3: =SUM(O3:S3) -> 1 | U3: =IFERROR((VLOOKUP(A3,'links de acesso'!A:B,2,0)),"\\192.168.0.4\Produtos\PRODUTO_PRONTA_ENTREGA\static\IMAGENS_PRODUTOS\SEM IMAGEM.jpg") -> \\192.168.0.4\Produtos\PRODUTO_PRONTA_ENTREGA\static\IMAGENS_PRODUTOS\SEM IMAGEM.jpg | V3: =IF(Tabela3[[#This Row],[LINK_IMAGEM]]="\\192.168.0.4\Produtos\PRODUTO_PRONTA_ENTREGA\static\IMAGENS_PRODUTOS\SEM IMAGEM.jpg","SEM IMAGEM","COM IMAGEM") -> SEM IMAGEM
A4: 271175 | B4: =IFERROR((VLOOKUP(A4,'[1]LISTA ETIQUETAS'!O:X,3,0)),"PRODUTO SEM ESTOQUE") -> EST BUFFET BENJAMIN (FREIJO NATURAL) | C4: =VLOOKUP(A4,'[1]LISTA ETIQUETAS'!$O:$BT,58,0) -> DPOT BUFFET | D4: =VLOOKUP(A4,'[1]LISTA ETIQUETAS'!$O:$BU,59,0) -> BUFFET BENJAMIN | E4: =IF(VLOOKUP(A4,'[1]LISTA ETIQUETAS'!O:W,4,0)="",(VLOOKUP(A4,'[1]LISTA ETIQUETAS'!O:W,7,0)),(VLOOKUP(A4,'[1]LISTA ETIQUETAS'!O:W,4,0))) -> 2.4 | F4: =IF(VLOOKUP(A4,'[1]LISTA ETIQUETAS'!O:W,5,0)="",(VLOOKUP(A4,'[1]LISTA ETIQUETAS'!O:W,8,0)),(VLOOKUP(A4,'[1]LISTA ETIQUETAS'!O:W,5,0))) -> 0.5 | G4: =IF(VLOOKUP(A4,'[1]LISTA ETIQUETAS'!O:W,6,0)="",(VLOOKUP(A4,'[1]LISTA ETIQUETAS'!O:W,9,0)),(VLOOKUP(A4,'[1]LISTA ETIQUETAS'!O:W,5,0))) -> 0.75 | H4: =IFERROR((VLOOKUP(A4,'[1]LISTA ETIQUETAS'!O:X,10,0)),"") -> 0 | I4: =IFERROR((VLOOKUP(A4,'[1]LISTA ETIQUETAS'!O:Z,12,0)),"") -> 0 | J4: =VLOOKUP(A4,'[1]LISTA ETIQUETAS'!$O:$AA,13,0) -> 0 | K4: =IFERROR(I4-I4*J4,"") -> 0 | L4: =IF(VLOOKUP(A4,'[1]LISTA ETIQUETAS'!O:AC,15,0)="","",(VLOOKUP(A4,'[1]LISTA ETIQUETAS'!O:AC,15,0))) | M4: =VLOOKUP(A4,'[1]LISTA ETIQUETAS'!$O:$BS,57,0) -> 0 | N4: =IF(M4=0,A4,M4) -> 271175 | S4: =_xlfn.XLOOKUP($A4,'[1]LISTA ETIQUETAS'!$O:$O,'[1]LISTA ETIQUETAS'!H:H,"",0) -> 1 | T4: =SUM(O4:S4) -> 1 | U4: =IFERROR((VLOOKUP(A4,'links de acesso'!A:B,2,0)),"\\192.168.0.4\Produtos\PRODUTO_PRONTA_ENTREGA\static\IMAGENS_PRODUTOS\SEM IMAGEM.jpg") -> \\192.168.0.4\Produtos\PRODUTO_PRONTA_ENTREGA\static\IMAGENS_PRODUTOS\SEM IMAGEM.jpg
A5: 171454 | B5: =IFERROR((VLOOKUP(A5,'[1]LISTA ETIQUETAS'!O:X,3,0)),"PRODUTO SEM ESTOQUE") -> EST BUFFET CORTEN (4P/2G) (RESINA SAY F100) (ACO CORTEN) | C5: =VLOOKUP(A5,'[1]LISTA ETIQUETAS'!$O:$BT,58,0) -> DPOT BUFFET | D5: =VLOOKUP(A5,'[1]LISTA ETIQUETAS'!$O:$BU,59,0) -> BUFFET CORTEN | E5: =IF(VLOOKUP(A5,'[1]LISTA ETIQUETAS'!O:W,4,0)="",(VLOOKUP(A5,'[1]LISTA ETIQUETAS'!O:W,7,0)),(VLOOKUP(A5,'[1]LISTA ETIQUETAS'!O:W,4,0))) -> 2.7 | F5: =IF(VLOOKUP(A5,'[1]LISTA ETIQUETAS'!O:W,5,0)="",(VLOOKUP(A5,'[1]LISTA ETIQUETAS'!O:W,8,0)),(VLOOKUP(A5,'[1]LISTA ETIQUETAS'!O:W,5,0))) -> 0.5 | G5: =IF(VLOOKUP(A5,'[1]LISTA ETIQUETAS'!O:W,6,0)="",(VLOOKUP(A5,'[1]LISTA ETIQUETAS'!O:W,9,0)),(VLOOKUP(A5,'[1]LISTA ETIQUETAS'!O:W,5,0))) -> 0.73 | H5: =IFERROR((VLOOKUP(A5,'[1]LISTA ETIQUETAS'!O:X,10,0)),"") -> 0 | I5: =IFERROR((VLOOKUP(A5,'[1]LISTA ETIQUETAS'!O:Z,12,0)),"") -> 0 | J5: =VLOOKUP(A5,'[1]LISTA ETIQUETAS'!$O:$AA,13,0) -> 0 | K5: =IFERROR(I5-I5*J5,"") -> 0 | L5: =IF(VLOOKUP(A5,'[1]LISTA ETIQUETAS'!O:AC,15,0)="","",(VLOOKUP(A5,'[1]LISTA ETIQUETAS'!O:AC,15,0))) | M5: =VLOOKUP(A5,'[1]LISTA ETIQUETAS'!$O:$BS,57,0) -> 0 | N5: =IF(M5=0,A5,M5) -> 171454 | S5: =_xlfn.XLOOKUP($A5,'[1]LISTA ETIQUETAS'!$O:$O,'[1]LISTA ETIQUETAS'!H:H,"",0) -> 1 | T5: =SUM(O5:S5) -> 1 | U5: =IFERROR((VLOOKUP(A5,'links de acesso'!A:B,2,0)),"\\192.168.0.4\Produtos\PRODUTO_PRONTA_ENTREGA\static\IMAGENS_PRODUTOS\SEM IMAGEM.jpg") -> \\192.168.0.4\Produtos\PRODUTO_PRONTA_ENTREGA\static\IMAGENS_PRODUTOS\SEM IMAGEM.jpg
A6: 172914 | B6: =IFERROR((VLOOKUP(A6,'[1]LISTA ETIQUETAS'!O:X,3,0)),"PRODUTO SEM ESTOQUE") -> EST BUFFET CORTEN (4P/2G) (RESINA SAY L138) (ACO CORTEN) | C6: =VLOOKUP(A6,'[1]LISTA ETIQUETAS'!$O:$BT,58,0) -> DPOT BUFFET | D6: =VLOOKUP(A6,'[1]LISTA ETIQUETAS'!$O:$BU,59,0) -> BUFFET CORTEN | E6: =IF(VLOOKUP(A6,'[1]LISTA ETIQUETAS'!O:W,4,0)="",(VLOOKUP(A6,'[1]LISTA ETIQUETAS'!O:W,7,0)),(VLOOKUP(A6,'[1]LISTA ETIQUETAS'!O:W,4,0))) -> 2.7 | F6: =IF(VLOOKUP(A6,'[1]LISTA ETIQUETAS'!O:W,5,0)="",(VLOOKUP(A6,'[1]LISTA ETIQUETAS'!O:W,8,0)),(VLOOKUP(A6,'[1]LISTA ETIQUETAS'!O:W,5,0))) -> 0.5 | G6: =IF(VLOOKUP(A6,'[1]LISTA ETIQUETAS'!O:W,6,0)="",(VLOOKUP(A6,'[1]LISTA ETIQUETAS'!O:W,9,0)),(VLOOKUP(A6,'[1]LISTA ETIQUETAS'!O:W,5,0))) -> 0.73 | H6: =IFERROR((VLOOKUP(A6,'[1]LISTA ETIQUETAS'!O:X,10,0)),"") -> 0 | I6: =IFERROR((VLOOKUP(A6,'[1]LISTA ETIQUETAS'!O:Z,12,0)),"") -> 0 | J6: =VLOOKUP(A6,'[1]LISTA ETIQUETAS'!$O:$AA,13,0) -> 0 | K6: =IFERROR(I6-I6*J6,"") -> 0 | L6: =IF(VLOOKUP(A6,'[1]LISTA ETIQUETAS'!O:AC,15,0)="","",(VLOOKUP(A6,'[1]LISTA ETIQUETAS'!O:AC,15,0))) | M6: =VLOOKUP(A6,'[1]LISTA ETIQUETAS'!$O:$BS,57,0) -> 0 | N6: =IF(M6=0,A6,M6) -> 172914 | S6: =_xlfn.XLOOKUP($A6,'[1]LISTA ETIQUETAS'!$O:$O,'[1]LISTA ETIQUETAS'!H:H,"",0) -> 1 | T6: =SUM(O6:S6) -> 1 | U6: =IFERROR((VLOOKUP(A6,'links de acesso'!A:B,2,0)),"\\192.168.0.4\Produtos\PRODUTO_PRONTA_ENTREGA\static\IMAGENS_PRODUTOS\SEM IMAGEM.jpg") -> \\192.168.0.4\Produtos\PRODUTO_PRONTA_ENTREGA\static\IMAGENS_PRODUTOS\SEM IMAGEM.jpg
A7: 339729 | B7: =IFERROR((VLOOKUP(A7,'[1]LISTA ETIQUETAS'!O:X,3,0)),"PRODUTO SEM ESTOQUE") -> EST BUFFET GAFANHOTO (INFERIOR) (MADEIRA PEROBA CLARA) | C7: =VLOOKUP(A7,'[1]LISTA ETIQUETAS'!$O:$BT,58,0) -> DPOT BUFFET | D7: =VLOOKUP(A7,'[1]LISTA ETIQUETAS'!$O:$BU,59,0) -> BUFFET GAFANHOTO | E7: =IF(VLOOKUP(A7,'[1]LISTA ETIQUETAS'!O:W,4,0)="",(VLOOKUP(A7,'[1]LISTA ETIQUETAS'!O:W,7,0)),(VLOOKUP(A7,'[1]LISTA ETIQUETAS'!O:W,4,0))) -> 2.7 | F7: =IF(VLOOKUP(A7,'[1]LISTA ETIQUETAS'!O:W,5,0)="",(VLOOKUP(A7,'[1]LISTA ETIQUETAS'!O:W,8,0)),(VLOOKUP(A7,'[1]LISTA ETIQUETAS'!O:W,5,0))) -> 0.5 | G7: =IF(VLOOKUP(A7,'[1]LISTA ETIQUETAS'!O:W,6,0)="",(VLOOKUP(A7,'[1]LISTA ETIQUETAS'!O:W,9,0)),(VLOOKUP(A7,'[1]LISTA ETIQUETAS'!O:W,5,0))) -> 0.67 | H7: =IFERROR((VLOOKUP(A7,'[1]LISTA ETIQUETAS'!O:X,10,0)),"") -> 0 | I7: =IFERROR((VLOOKUP(A7,'[1]LISTA ETIQUETAS'!O:Z,12,0)),"") -> 0 | J7: =VLOOKUP(A7,'[1]LISTA ETIQUETAS'!$O:$AA,13,0) -> 0 | K7: =IFERROR(I7-I7*J7,"") -> 0 | L7: =IF(VLOOKUP(A7,'[1]LISTA ETIQUETAS'!O:AC,15,0)="","",(VLOOKUP(A7,'[1]LISTA ETIQUETAS'!O:AC,15,0))) | M7: =VLOOKUP(A7,'[1]LISTA ETIQUETAS'!$O:$BS,57,0) -> 0 | N7: =IF(M7=0,A7,M7) -> 339729 | S7: =_xlfn.XLOOKUP($A7,'[1]LISTA ETIQUETAS'!$O:$O,'[1]LISTA ETIQUETAS'!H:H,"",0) -> 1 | T7: =SUM(O7:S7) -> 1 | U7: =IFERROR((VLOOKUP(A7,'links de acesso'!A:B,2,0)),"\\192.168.0.4\Produtos\PRODUTO_PRONTA_ENTREGA\static\IMAGENS_PRODUTOS\SEM IMAGEM.jpg") -> \\192.168.0.4\Produtos\PRODUTO_PRONTA_ENTREGA\static\IMAGENS_PRODUTOS\SEM IMAGEM.jpg
A8: 400828 | B8: =IFERROR((VLOOKUP(A8,'[1]LISTA ETIQUETAS'!O:X,3,0)),"PRODUTO SEM ESTOQUE") -> EST BUFFET ITA (3P) (M2 V LACTEA) (FREIJO EBANIZADO) | C8: =VLOOKUP(A8,'[1]LISTA ETIQUETAS'!$O:$BT,58,0) -> DPOT BUFFET | D8: =VLOOKUP(A8,'[1]LISTA ETIQUETAS'!$O:$BU,59,0) -> BUFFET ITA | E8: =IF(VLOOKUP(A8,'[1]LISTA ETIQUETAS'!O:W,4,0)="",(VLOOKUP(A8,'[1]LISTA ETIQUETAS'!O:W,7,0)),(VLOOKUP(A8,'[1]LISTA ETIQUETAS'!O:W,4,0))) -> 1.89 | F8: =IF(VLOOKUP(A8,'[1]LISTA ETIQUETAS'!O:W,5,0)="",(VLOOKUP(A8,'[1]LISTA ETIQUETAS'!O:W,8,0)),(VLOOKUP(A8,'[1]LISTA ETIQUETAS'!O:W,5,0))) -> 0.5 | G8: =IF(VLOOKUP(A8,'[1]LISTA ETIQUETAS'!O:W,6,0)="",(VLOOKUP(A8,'[1]LISTA ETIQUETAS'!O:W,9,0)),(VLOOKUP(A8,'[1]LISTA ETIQUETAS'!O:W,5,0))) -> 0.78 | H8: =IFERROR((VLOOKUP(A8,'[1]LISTA ETIQUETAS'!O:X,10,0)),"") -> 0 | I8: =IFERROR((VLOOKUP(A8,'[1]LISTA ETIQUETAS'!O:Z,12,0)),"") -> 73315.65 | J8: =VLOOKUP(A8,'[1]LISTA ETIQUETAS'!$O:$AA,13,0) -> 0.35 | K8: =IFERROR(I8-I8*J8,"") -> 47655.173 | L8: =IF(VLOOKUP(A8,'[1]LISTA ETIQUETAS'!O:AC,15,0)="","",(VLOOKUP(A8,'[1]LISTA ETIQUETAS'!O:AC,15,0))) | M8: =VLOOKUP(A8,'[1]LISTA ETIQUETAS'!$O:$BS,57,0) -> 0 | N8: =IF(M8=0,A8,M8) -> 400828 | S8: =_xlfn.XLOOKUP($A8,'[1]LISTA ETIQUETAS'!$O:$O,'[1]LISTA ETIQUETAS'!H:H,"",0) -> 1 | T8: =SUM(O8:S8) -> 1 | U8: =IFERROR((VLOOKUP(A8,'links de acesso'!A:B,2,0)),"\\192.168.0.4\Produtos\PRODUTO_PRONTA_ENTREGA\static\IMAGENS_PRODUTOS\SEM IMAGEM.jpg") -> \\192.168.0.4\Produtos\PRODUTO_PRONTA_ENTREGA\static\IMAGENS_PRODUTOS\SEM IMAGEM.jpg
A9: 224968 | B9: =IFERROR((VLOOKUP(A9,'[1]LISTA ETIQUETAS'!O:X,3,0)),"PRODUTO SEM ESTOQUE") -> EST BUFFET OBLONGO (P FERRO CLARO) (PTO FSC SOLID) | C9: =VLOOKUP(A9,'[1]LISTA ETIQUETAS'!$O:$BT,58,0) -> DPOT BUFFET | D9: =VLOOKUP(A9,'[1]LISTA ETIQUETAS'!$O:$BU,59,0) -> BUFFET OBLONGO | E9: =IF(VLOOKUP(A9,'[1]LISTA ETIQUETAS'!O:W,4,0)="",(VLOOKUP(A9,'[1]LISTA ETIQUETAS'!O:W,7,0)),(VLOOKUP(A9,'[1]LISTA ETIQUETAS'!O:W,4,0))) -> 2.5 | F9: =IF(VLOOKUP(A9,'[1]LISTA ETIQUETAS'!O:W,5,0)="",(VLOOKUP(A9,'[1]LISTA ETIQUETAS'!O:W,8,0)),(VLOOKUP(A9,'[1]LISTA ETIQUETAS'!O:W,5,0))) -> 0.5 | G9: =IF(VLOOKUP(A9,'[1]LISTA ETIQUETAS'!O:W,6,0)="",(VLOOKUP(A9,'[1]LISTA ETIQUETAS'!O:W,9,0)),(VLOOKUP(A9,'[1]LISTA ETIQUETAS'!O:W,5,0))) -> 0.74 | H9: =IFERROR((VLOOKUP(A9,'[1]LISTA ETIQUETAS'!O:X,10,0)),"") -> 0 | I9: =IFERROR((VLOOKUP(A9,'[1]LISTA ETIQUETAS'!O:Z,12,0)),"") -> 0 | J9: =VLOOKUP(A9,'[1]LISTA ETIQUETAS'!$O:$AA,13,0) -> 0 | K9: =IFERROR(I9-I9*J9,"") -> 0 | L9: =IF(VLOOKUP(A9,'[1]LISTA ETIQUETAS'!O:AC,15,0)="","",(VLOOKUP(A9,'[1]LISTA ETIQUETAS'!O:AC,15,0))) | M9: =VLOOKUP(A9,'[1]LISTA ETIQUETAS'!$O:$BS,57,0) -> 0 | N9: =IF(M9=0,A9,M9) -> 224968 | S9: =_xlfn.XLOOKUP($A9,'[1]LISTA ETIQUETAS'!$O:$O,'[1]LISTA ETIQUETAS'!H:H,"",0) -> 1 | T9: =SUM(O9:S9) -> 1 | U9: =IFERROR((VLOOKUP(A9,'links de acesso'!A:B,2,0)),"\\192.168.0.4\Produtos\PRODUTO_PRONTA_ENTREGA\static\IMAGENS_PRODUTOS\SEM IMAGEM.jpg") -> \\192.168.0.4\Produtos\PRODUTO_PRONTA_ENTREGA\static\IMAGENS_PRODUTOS\SEM IMAGEM.jpg
A10: 63146 | B10: =IFERROR((VLOOKUP(A10,'[1]LISTA ETIQUETAS'!O:X,3,0)),"PRODUTO SEM ESTOQUE") -> EST BIOMBO ESPECIAL (RATTAN COR 3) | C10: =VLOOKUP(A10,'[1]LISTA ETIQUETAS'!$O:$BT,58,0) -> DPOT ACESSORIOS | D10: =VLOOKUP(A10,'[1]LISTA ETIQUETAS'!$O:$BU,59,0) -> BIOMBO ESPECIAL | E10: =IF(VLOOKUP(A10,'[1]LISTA ETIQUETAS'!O:W,4,0)="",(VLOOKUP(A10,'[1]LISTA ETIQUETAS'!O:W,7,0)),(VLOOKUP(A10,'[1]LISTA ETIQUETAS'!O:W,4,0))) -> 0.5 | F10: =IF(VLOOKUP(A10,'[1]LISTA ETIQUETAS'!O:W,5,0)="",(VLOOKUP(A10,'[1]LISTA ETIQUETAS'!O:W,8,0)),(VLOOKUP(A10,'[1]LISTA ETIQUETAS'!O:W,5,0))) -> 0.05 | G10: =IF(VLOOKUP(A10,'[1]LISTA ETIQUETAS'!O:W,6,0)="",(VLOOKUP(A10,'[1]LISTA ETIQUETAS'!O:W,9,0)),(VLOOKUP(A10,'[1]LISTA ETIQUETAS'!O:W,5,0))) -> 1.3 | H10: =IFERROR((VLOOKUP(A10,'[1]LISTA ETIQUETAS'!O:X,10,0)),"") -> 0 | I10: =IFERROR((VLOOKUP(A10,'[1]LISTA ETIQUETAS'!O:Z,12,0)),"") -> 0 | J10: =VLOOKUP(A10,'[1]LISTA ETIQUETAS'!$O:$AA,13,0) -> 0 | K10: =IFERROR(I10-I10*J10,"") -> 0 | L10: =IF(VLOOKUP(A10,'[1]LISTA ETIQUETAS'!O:AC,15,0)="","",(VLOOKUP(A10,'[1]LISTA ETIQUETAS'!O:AC,15,0))) | M10: =VLOOKUP(A10,'[1]LISTA ETIQUETAS'!$O:$BS,57,0) -> 0 | N10: =IF(M10=0,A10,M10) -> 63146 | S10: =_xlfn.XLOOKUP($A10,'[1]LISTA ETIQUETAS'!$O:$O,'[1]LISTA ETIQUETAS'!H:H,"",0) -> 8 | T10: =SUM(O10:S10) -> 8 | U10: =IFERROR((VLOOKUP(A10,'links de acesso'!A:B,2,0)),"\\192.168.0.4\Produtos\PRODUTO_PRONTA_ENTREGA\static\IMAGENS_PRODUTOS\SEM IMAGEM.jpg") -> \\192.168.0.4\Produtos\PRODUTO_PRONTA_ENTREGA\static\IMAGENS_PRODUTOS\SEM IMAGEM.jpg
A11: 78080 | B11: =IFERROR((VLOOKUP(A11,'[1]LISTA ETIQUETAS'!O:X,3,0)),"PRODUTO SEM ESTOQUE") -> EST BIOMBO MEMORIAS 190X62X180H FREIJO/TECIDO 3 FOLHAS | C11: =VLOOKUP(A11,'[1]LISTA ETIQUETAS'!$O:$BT,58,0) -> DPOT ACESSORIOS | D11: =VLOOKUP(A11,'[1]LISTA ETIQUETAS'!$O:$BU,59,0) -> BIOMBO MEMORIAS | E11: =IF(VLOOKUP(A11,'[1]LISTA ETIQUETAS'!O:W,4,0)="",(VLOOKUP(A11,'[1]LISTA ETIQUETAS'!O:W,7,0)),(VLOOKUP(A11,'[1]LISTA ETIQUETAS'!O:W,4,0))) -> 0 | F11: =IF(VLOOKUP(A11,'[1]LISTA ETIQUETAS'!O:W,5,0)="",(VLOOKUP(A11,'[1]LISTA ETIQUETAS'!O:W,8,0)),(VLOOKUP(A11,'[1]LISTA ETIQUETAS'!O:W,5,0))) -> 0 | G11: =IF(VLOOKUP(A11,'[1]LISTA ETIQUETAS'!O:W,6,0)="",(VLOOKUP(A11,'[1]LISTA ETIQUETAS'!O:W,9,0)),(VLOOKUP(A11,'[1]LISTA ETIQUETAS'!O:W,5,0))) -> 0 | H11: =IFERROR((VLOOKUP(A11,'[1]LISTA ETIQUETAS'!O:X,10,0)),"") -> 0 | I11: =IFERROR((VLOOKUP(A11,'[1]LISTA ETIQUETAS'!O:Z,12,0)),"") -> 0 | J11: =VLOOKUP(A11,'[1]LISTA ETIQUETAS'!$O:$AA,13,0) -> 0.35 | K11: =IFERROR(I11-I11*J11,"") -> 0 | L11: =IF(VLOOKUP(A11,'[1]LISTA ETIQUETAS'!O:AC,15,0)="","",(VLOOKUP(A11,'[1]LISTA ETIQUETAS'!O:AC,15,0))) | M11: =VLOOKUP(A11,'[1]LISTA ETIQUETAS'!$O:$BS,57,0) -> 0 | N11: =IF(M11=0,A11,M11) -> 78080 | S11: =_xlfn.XLOOKUP($A11,'[1]LISTA ETIQUETAS'!$O:$O,'[1]LISTA ETIQUETAS'!H:H,"",0) -> 1 | T11: =SUM(O11:S11) -> 1 | U11: =IFERROR((VLOOKUP(A11,'links de acesso'!A:B,2,0)),"\\192.168.0.4\Produtos\PRODUTO_PRONTA_ENTREGA\static\IMAGENS_PRODUTOS\SEM IMAGEM.jpg") -> \\192.168.0.4\Produtos\PRODUTO_PRONTA_ENTREGA\static\IMAGENS_PRODUTOS\SEM IMAGEM.jpg
A12: 188022 | B12: =IFERROR((VLOOKUP(A12,'[1]LISTA ETIQUETAS'!O:X,3,0)),"PRODUTO SEM ESTOQUE") -> EST BIOMBO RIPAS (PADRAO CLARO) | C12: =VLOOKUP(A12,'[1]LISTA ETIQUETAS'!$O:$BT,58,0) -> DPOT ACESSORIOS | D12: =VLOOKUP(A12,'[1]LISTA ETIQUETAS'!$O:$BU,59,0) -> BIOMBO RIPAS | E12: =IF(VLOOKUP(A12,'[1]LISTA ETIQUETAS'!O:W,4,0)="",(VLOOKUP(A12,'[1]LISTA ETIQUETAS'!O:W,7,0)),(VLOOKUP(A12,'[1]LISTA ETIQUETAS'!O:W,4,0))) -> 1.49 | F12: =IF(VLOOKUP(A12,'[1]LISTA ETIQUETAS'!O:W,5,0)="",(VLOOKUP(A12,'[1]LISTA ETIQUETAS'!O:W,8,0)),(VLOOKUP(A12,'[1]LISTA ETIQUETAS'!O:W,5,0))) -> 0.37 | G12: =IF(VLOOKUP(A12,'[1]LISTA ETIQUETAS'!O:W,6,0)="",(VLOOKUP(A12,'[1]LISTA ETIQUETAS'!O:W,9,0)),(VLOOKUP(A12,'[1]LISTA ETIQUETAS'!O:W,5,0))) -> 1.2 | H12: =IFERROR((VLOOKUP(A12,'[1]LISTA ETIQUETAS'!O:X,10,0)),"") -> 0 | I12: =IFERROR((VLOOKUP(A12,'[1]LISTA ETIQUETAS'!O:Z,12,0)),"") -> 0 | J12: =VLOOKUP(A12,'[1]LISTA ETIQUETAS'!$O:$AA,13,0) -> 0 | K12: =IFERROR(I12-I12*J12,"") -> 0 | L12: =IF(VLOOKUP(A12,'[1]LISTA ETIQUETAS'!O:AC,15,0)="","",(VLOOKUP(A12,'[1]LISTA ETIQUETAS'!O:AC,15,0))) | M12: =VLOOKUP(A12,'[1]LISTA ETIQUETAS'!$O:$BS,57,0) -> 0 | N12: =IF(M12=0,A12,M12) -> 188022 | S12: =_xlfn.XLOOKUP($A12,'[1]LISTA ETIQUETAS'!$O:$O,'[1]LISTA ETIQUETAS'!H:H,"",0) -> 1 | T12: =SUM(O12:S12) -> 1 | U12: =IFERROR((VLOOKUP(A12,'links de acesso'!A:B,2,0)),"\\192.168.0.4\Produtos\PRODUTO_PRONTA_ENTREGA\static\IMAGENS_PRODUTOS\SEM IMAGEM.jpg") -> \\192.168.0.4\Produtos\PRODUTO_PRONTA_ENTREGA\static\IMAGENS_PRODUTOS\SEM IMAGEM.jpg
A13: 205139 | B13: =IFERROR((VLOOKUP(A13,'[1]LISTA ETIQUETAS'!O:X,3,0)),"PRODUTO SEM ESTOQUE") -> EST CABIDEIRO ABAPORU (PADRAO) (FREIJO NATURAL) | C13: =VLOOKUP(A13,'[1]LISTA ETIQUETAS'!$O:$BT,58,0) -> DPOT ACESSORIOS | D13: =VLOOKUP(A13,'[1]LISTA ETIQUETAS'!$O:$BU,59,0) -> CABIDEIRO ABAPORU | E13: =IF(VLOOKUP(A13,'[1]LISTA ETIQUETAS'!O:W,4,0)="",(VLOOKUP(A13,'[1]LISTA ETIQUETAS'!O:W,7,0)),(VLOOKUP(A13,'[1]LISTA ETIQUETAS'!O:W,4,0))) -> 0.65 | F13: =IF(VLOOKUP(A13,'[1]LISTA ETIQUETAS'!O:W,5,0)="",(VLOOKUP(A13,'[1]LISTA ETIQUETAS'!O:W,8,0)),(VLOOKUP(A13,'[1]LISTA ETIQUETAS'!O:W,5,0))) -> 0 | G13: =IF(VLOOKUP(A13,'[1]LISTA ETIQUETAS'!O:W,6,0)="",(VLOOKUP(A13,'[1]LISTA ETIQUETAS'!O:W,9,0)),(VLOOKUP(A13,'[1]LISTA ETIQUETAS'!O:W,5,0))) -> 1.6 | H13: =IFERROR((VLOOKUP(A13,'[1]LISTA ETIQUETAS'!O:X,10,0)),"") -> 0.65 | I13: =IFERROR((VLOOKUP(A13,'[1]LISTA ETIQUETAS'!O:Z,12,0)),"") -> 0 | J13: =VLOOKUP(A13,'[1]LISTA ETIQUETAS'!$O:$AA,13,0) -> 0.5 | K13: =IFERROR(I13-I13*J13,"") -> 0 | L13: =IF(VLOOKUP(A13,'[1]LISTA ETIQUETAS'!O:AC,15,0)="","",(VLOOKUP(A13,'[1]LISTA ETIQUETAS'!O:AC,15,0))) | M13: =VLOOKUP(A13,'[1]LISTA ETIQUETAS'!$O:$BS,57,0) -> 0 | N13: =IF(M13=0,A13,M13) -> 205139 | S13: =_xlfn.XLOOKUP($A13,'[1]LISTA ETIQUETAS'!$O:$O,'[1]LISTA ETIQUETAS'!H:H,"",0) -> 1 | T13: =SUM(O13:S13) -> 1 | U13: =IFERROR((VLOOKUP(A13,'links de acesso'!A:B,2,0)),"\\192.168.0.4\Produtos\PRODUTO_PRONTA_ENTREGA\static\IMAGENS_PRODUTOS\SEM IMAGEM.jpg") -> \\192.168.0.4\Produtos\PRODUTO_PRONTA_ENTREGA\static\IMAGENS_PRODUTOS\SEM IMAGEM.jpg
A14: 200733 | B14: =IFERROR((VLOOKUP(A14,'[1]LISTA ETIQUETAS'!O:X,3,0)),"PRODUTO SEM ESTOQUE") -> EST CABIDEIRO ABAPORU (PADRAO) (LACA ACETINADA BRANCA) | C14: =VLOOKUP(A14,'[1]LISTA ETIQUETAS'!$O:$BT,58,0) -> DPOT ACESSORIOS | D14: =VLOOKUP(A14,'[1]LISTA ETIQUETAS'!$O:$BU,59,0) -> CABIDEIRO ABAPORU | E14: =IF(VLOOKUP(A14,'[1]LISTA ETIQUETAS'!O:W,4,0)="",(VLOOKUP(A14,'[1]LISTA ETIQUETAS'!O:W,7,0)),(VLOOKUP(A14,'[1]LISTA ETIQUETAS'!O:W,4,0))) -> 0.65 | F14: =IF(VLOOKUP(A14,'[1]LISTA ETIQUETAS'!O:W,5,0)="",(VLOOKUP(A14,'[1]LISTA ETIQUETAS'!O:W,8,0)),(VLOOKUP(A14,'[1]LISTA ETIQUETAS'!O:W,5,0))) -> 0 | G14: =IF(VLOOKUP(A14,'[1]LISTA ETIQUETAS'!O:W,6,0)="",(VLOOKUP(A14,'[1]LISTA ETIQUETAS'!O:W,9,0)),(VLOOKUP(A14,'[1]LISTA ETIQUETAS'!O:W,5,0))) -> 1.6 | H14: =IFERROR((VLOOKUP(A14,'[1]LISTA ETIQUETAS'!O:X,10,0)),"") -> 0 | I14: =IFERROR((VLOOKUP(A14,'[1]LISTA ETIQUETAS'!O:Z,12,0)),"") -> 0 | J14: =VLOOKUP(A14,'[1]LISTA ETIQUETAS'!$O:$AA,13,0) -> 0 | K14: =IFERROR(I14-I14*J14,"") -> 0 | L14: =IF(VLOOKUP(A14,'[1]LISTA ETIQUETAS'!O:AC,15,0)="","",(VLOOKUP(A14,'[1]LISTA ETIQUETAS'!O:AC,15,0))) | M14: =VLOOKUP(A14,'[1]LISTA ETIQUETAS'!$O:$BS,57,0) -> 0 | N14: =IF(M14=0,A14,M14) -> 200733 | S14: =_xlfn.XLOOKUP($A14,'[1]LISTA ETIQUETAS'!$O:$O,'[1]LISTA ETIQUETAS'!H:H,"",0) -> 1 | T14: =SUM(O14:S14) -> 1 | U14: =IFERROR((VLOOKUP(A14,'links de acesso'!A:B,2,0)),"\\192.168.0.4\Produtos\PRODUTO_PRONTA_ENTREGA\static\IMAGENS_PRODUTOS\SEM IMAGEM.jpg") -> \\192.168.0.4\Produtos\PRODUTO_PRONTA_ENTREGA\static\IMAGENS_PRODUTOS\SEM IMAGEM.jpg
A15: 174028 | B15: =IFERROR((VLOOKUP(A15,'[1]LISTA ETIQUETAS'!O:X,3,0)),"PRODUTO SEM ESTOQUE") -> EST CABIDEIRO GIRO (PAREDE) (ACO CARBONO LACA BRANCA) | C15: =VLOOKUP(A15,'[1]LISTA ETIQUETAS'!$O:$BT,58,0) -> DPOT ACESSORIOS | D15: =VLOOKUP(A15,'[1]LISTA ETIQUETAS'!$O:$BU,59,0) -> CABIDEIRO GIRO | E15: =IF(VLOOKUP(A15,'[1]LISTA ETIQUETAS'!O:W,4,0)="",(VLOOKUP(A15,'[1]LISTA ETIQUETAS'!O:W,7,0)),(VLOOKUP(A15,'[1]LISTA ETIQUETAS'!O:W,4,0))) -> 0.36 | F15: =IF(VLOOKUP(A15,'[1]LISTA ETIQUETAS'!O:W,5,0)="",(VLOOKUP(A15,'[1]LISTA ETIQUETAS'!O:W,8,0)),(VLOOKUP(A15,'[1]LISTA ETIQUETAS'!O:W,5,0))) -> 0 | G15: =IF(VLOOKUP(A15,'[1]LISTA ETIQUETAS'!O:W,6,0)="",(VLOOKUP(A15,'[1]LISTA ETIQUETAS'!O:W,9,0)),(VLOOKUP(A15,'[1]LISTA ETIQUETAS'!O:W,5,0))) -> 2.15 | H15: =IFERROR((VLOOKUP(A15,'[1]LISTA ETIQUETAS'!O:X,10,0)),"") -> 0 | I15: =IFERROR((VLOOKUP(A15,'[1]LISTA ETIQUETAS'!O:Z,12,0)),"") -> 0 | J15: =VLOOKUP(A15,'[1]LISTA ETIQUETAS'!$O:$AA,13,0) -> 0.5 | K15: =IFERROR(I15-I15*J15,"") -> 0 | L15: =IF(VLOOKUP(A15,'[1]LISTA ETIQUETAS'!O:AC,15,0)="","",(VLOOKUP(A15,'[1]LISTA ETIQUETAS'!O:AC,15,0))) | M15: =VLOOKUP(A15,'[1]LISTA ETIQUETAS'!$O:$BS,57,0) -> 0 | N15: =IF(M15=0,A15,M15) -> 174028 | S15: =_xlfn.XLOOKUP($A15,'[1]LISTA ETIQUETAS'!$O:$O,'[1]LISTA ETIQUETAS'!H:H,"",0) -> 2 | T15: =SUM(O15:S15) -> 2 | U15: =IFERROR((VLOOKUP(A15,'links de acesso'!A:B,2,0)),"\\192.168.0.4\Produtos\PRODUTO_PRONTA_ENTREGA\static\IMAGENS_PRODUTOS\SEM IMAGEM.jpg") -> \\192.168.0.4\Produtos\PRODUTO_PRONTA_ENTREGA\static\IMAGENS_PRODUTOS\SEM IMAGEM.jpg
... A891: 229381 | B891: =IFERROR((VLOOKUP(A891,'[1]LISTA ETIQUETAS'!O:X,3,0)),"PRODUTO SEM ESTOQUE") -> EST TAMPO MINI PICK (MODELO C) (BATEIG BLUE) | C891: =VLOOKUP(A891,'[1]LISTA ETIQUETAS'!$O:$BT,58,0) -> TAMPO MARMORE | D891: =VLOOKUP(A891,'[1]LISTA ETIQUETAS'!$O:$BU,59,0) -> TAMPO MINI PICK | E891: =IF(VLOOKUP(A891,'[1]LISTA ETIQUETAS'!O:W,4,0)="",(VLOOKUP(A891,'[1]LISTA ETIQUETAS'!O:W,7,0)),(VLOOKUP(A891,'[1]LISTA ETIQUETAS'!O:W,4,0))) -> 0.85 | F891: =IF(VLOOKUP(A891,'[1]LISTA ETIQUETAS'!O:W,5,0)="",(VLOOKUP(A891,'[1]LISTA ETIQUETAS'!O:W,8,0)),(VLOOKUP(A891,'[1]LISTA ETIQUETAS'!O:W,5,0))) -> 0.5 | G891: =IF(VLOOKUP(A891,'[1]LISTA ETIQUETAS'!O:W,6,0)="",(VLOOKUP(A891,'[1]LISTA ETIQUETAS'!O:W,9,0)),(VLOOKUP(A891,'[1]LISTA ETIQUETAS'!O:W,5,0))) -> 0.02 | H891: =IFERROR((VLOOKUP(A891,'[1]LISTA ETIQUETAS'!O:X,10,0)),"") -> 0 | I891: =IFERROR((VLOOKUP(A891,'[1]LISTA ETIQUETAS'!O:Z,12,0)),"") -> 0 | J891: =VLOOKUP(A891,'[1]LISTA ETIQUETAS'!$O:$AA,13,0) -> 0.5 | K891: =IFERROR(I891-I891*J891,"") -> 0 | L891: =IF(VLOOKUP(A891,'[1]LISTA ETIQUETAS'!O:AC,15,0)="","",(VLOOKUP(A891,'[1]LISTA ETIQUETAS'!O:AC,15,0))) | M891: =VLOOKUP(A891,'[1]LISTA ETIQUETAS'!$O:$BS,57,0) -> 0 | N891: =IF(M891=0,A891,M891) -> 229381 | S891: =_xlfn.XLOOKUP($A891,'[1]LISTA ETIQUETAS'!$O:$O,'[1]LISTA ETIQUETAS'!H:H,"",0) -> 3 | T891: =SUM(O891:S891) -> 3 | U891: =IFERROR((VLOOKUP(A891,'links de acesso'!A:B,2,0)),"\\192.168.0.4\Produtos\PRODUTO_PRONTA_ENTREGA\static\IMAGENS_PRODUTOS\SEM IMAGEM.jpg") -> \\192.168.0.4\Produtos\PRODUTO_PRONTA_ENTREGA\static\IMAGENS_PRODUTOS\SEM IMAGEM.jpg

Sheet links de acesso
A1: LINK | B1: LINK | C1: LINK | D1: LINK | E1: LINK | F1: LINK
A2: 234552 | B2: \\192.168.0.4\Produtos\PRODUTO_PRONTA_ENTREGA\static\IMAGENS_PRODUTOS\_APARADOR APOIO PITT_234552.jpg | C2: APARADOR APOIO PITT | D2: 234552 | F2: \\192.168.0.4\Produtos\PRODUTO_PRONTA_ENTREGA\static\IMAGENS_PRODUTOS\SEM IMAGEM.jpg
A3: 274937 | B3: \\192.168.0.4\Produtos\PRODUTO_PRONTA_ENTREGA\static\IMAGENS_PRODUTOS\_APARADOR AYLA_274937.jpg | C3: APARADOR AYLA | D3: 274937
A4: 378480 | B4: \\192.168.0.4\Produtos\PRODUTO_PRONTA_ENTREGA\static\IMAGENS_PRODUTOS\_APARADOR BALLET_378480.jpg | C4: APARADOR BALLET | D4: 378480
A5: 157048 | B5: \\192.168.0.4\Produtos\PRODUTO_PRONTA_ENTREGA\static\IMAGENS_PRODUTOS\_APARADOR CALVIN_157048.jpg | C5: APARADOR CALVIN | D5: 157048
A6: 336562 | B6: \\192.168.0.4\Produtos\PRODUTO_PRONTA_ENTREGA\static\IMAGENS_PRODUTOS\_APARADOR VELL_336562.jpg | C6: APARADOR VELL | D6: 336562
A7: 182711 | B7: \\192.168.0.4\Produtos\PRODUTO_PRONTA_ENTREGA\static\IMAGENS_PRODUTOS\APARADOR AMALFI_182711.jpg | C7: APARADOR AMALFI | D7: 182711
A8: 151597 | B8: \\192.168.0.4\Produtos\PRODUTO_PRONTA_ENTREGA\static\IMAGENS_PRODUTOS\APARADOR BALI_151597.jpg | C8: APARADOR BALI | D8: 151597
A9: 210381 | B9: \\192.168.0.4\Produtos\PRODUTO_PRONTA_ENTREGA\static\IMAGENS_PRODUTOS\APARADOR BARBENA_210381.jpg | C9: APARADOR BARBENA | D9: 210381
A10: 151450 | B10: \\192.168.0.4\Produtos\PRODUTO_PRONTA_ENTREGA\static\IMAGENS_PRODUTOS\APARADOR CARAJAS_151450.jpg | C10: APARADOR CARAJAS | D10: 151450
A11: 228598 | B11: \\192.168.0.4\Produtos\PRODUTO_PRONTA_ENTREGA\static\IMAGENS_PRODUTOS\APARADOR COMPOSTA_228598.jpg | C11: APARADOR COMPOSTA | D11: 228598
A12: 127041 | B12: \\192.168.0.4\Produtos\PRODUTO_PRONTA_ENTREGA\static\IMAGENS_PRODUTOS\APARADOR ELLE_127041.jpg | C12: APARADOR ELLE | D12: 127041
A13: 63439 | B13: \\192.168.0.4\Produtos\PRODUTO_PRONTA_ENTREGA\static\IMAGENS_PRODUTOS\APARADOR JOVE_63439.jpg | C13: APARADOR JOVE | D13: 63439
A14: 210409 | B14: \\192.168.0.4\Produtos\PRODUTO_PRONTA_ENTREGA\static\IMAGENS_PRODUTOS\APARADOR LISA_210409.jpg | C14: APARADOR LISA | D14: 210409
... A533: 124405 | B533: \\192.168.0.4\Produtos\PRODUTO_PRONTA_ENTREGA\static\IMAGENS_PRODUTOS\MESA LATERAL FIX_124405.jpg | C533: MESA LATERAL FIX | D533: 124405
B534: \\192.168.0.4\Produtos\PRODUTO_PRONTA_ENTREGA\static\IMAGENS_PRODUTOS\MESA LATERAL FLY_275790.jpg | C534: MESA LATERAL FLY | D534: 275790
A535: 154011 | B535: \\192.168.0.4\Produtos\PRODUTO_PRONTA_ENTREGA\static\IMAGENS_PRODUTOS\MESA LATERAL GESTO_154011.jpg | C535: MESA LATERAL GESTO | D535: 154011
A536: 334223 | B536: \\192.168.0.4\Produtos\PRODUTO_PRONTA_ENTREGA\static\IMAGENS_PRODUTOS\MESA LATERAL GESTO_334223.jpg | C536: MESA LATERAL GESTO | D536: 334223
A537: 334225 | B537: \\192.168.0.4\Produtos\PRODUTO_PRONTA_ENTREGA\static\IMAGENS_PRODUTOS\MESA LATERAL GESTO_334225.jpg | C537: MESA LATERAL GESTO | D537: 334225
A538: 151501 | B538: \\192.168.0.4\Produtos\PRODUTO_PRONTA_ENTREGA\static\IMAGENS_PRODUTOS\MESA LATERAL IPANEMA_151501.jpg | C538: MESA LATERAL IPANEMA | D538: 151501
A539: 156587 | B539: \\192.168.0.4\Produtos\PRODUTO_PRONTA_ENTREGA\static\IMAGENS_PRODUTOS\MESA LATERAL IPANEMA_156587.jpg | C539: MESA LATERAL IPANEMA | D539: 156587
A540: 219074 | B540: \\192.168.0.4\Produtos\PRODUTO_PRONTA_ENTREGA\static\IMAGENS_PRODUTOS\MESA LATERAL IPANEMA_219074.jpg | C540: MESA LATERAL IPANEMA | D540: 219074
A541: 231135 | B541: \\192.168.0.4\Produtos\PRODUTO_PRONTA_ENTREGA\static\IMAGENS_PRODUTOS\MESA LATERAL JOAQUINA_231135.jpg | C541: MESA LATERAL JOAQUINA | D541: 231135
A542: 231138 | B542: \\192.168.0.4\Produtos\PRODUTO_PRONTA_ENTREGA\static\IMAGENS_PRODUTOS\MESA LATERAL JOAQUINA_231138.jpg | C542: MESA LATERAL JOAQUINA | D542: 231138
A543: 269934 | B543: \\192.168.0.4\Produtos\PRODUTO_PRONTA_ENTREGA\static\IMAGENS_PRODUTOS\MESA LATERAL JUNO_269934.jpg | C543: MESA LATERAL JUNO | D543: 269934
A544: 223240 | B544: \\192.168.0.4\Produtos\PRODUTO_PRONTA_ENTREGA\static\IMAGENS_PRODUTOS\MESA LATERAL KEND_223240.jpg | C544: MESA LATERAL KEND | D544: 223240
A545: 178687 | B545: \\192.168.0.4\Produtos\PRODUTO_PRONTA_ENTREGA\static\IMAGENS_PRODUTOS\MESA LATERAL LARA_178687.jpg | C545: MESA LATERAL LARA | D545: 178687
A546: 210420 | B546: \\192.168.0.4\Produtos\PRODUTO_PRONTA_ENTREGA\static\IMAGENS_PRODUTOS\MESA LATERAL LISA_210420.jpg | C546: MESA LATERAL LISA | D546: 210420
... A566: 113368 | B566: \\192.168.0.4\Produtos\PRODUTO_PRONTA_ENTREGA\static\IMAGENS_PRODUTOS\MESA LATERAL ONDA INFANTIL_113368.jpg | C566: MESA LATERAL ONDA INFANTIL | D566: 113368
B567: \\192.168.0.4\Produtos\PRODUTO_PRONTA_ENTREGA\static\IMAGENS_PRODUTOS\MESA LATERAL PACO_354545.jpg | C567: MESA LATERAL PACO | D567: 354545
B568: \\192.168.0.4\Produtos\PRODUTO_PRONTA_ENTREGA\static\IMAGENS_PRODUTOS\MESA LATERAL PACO_354548.jpg | C568: MESA LATERAL PACO | D568: 354548
A569: 257381 | B569: \\192.168.0.4\Produtos\PRODUTO_PRONTA_ENTREGA\static\IMAGENS_PRODUTOS\MESA LATERAL PALITO_257381.jpg | C569: MESA LATERAL PALITO | D569: 257381
A570: 77526 | B570: \\192.168.0.4\Produtos\PRODUTO_PRONTA_ENTREGA\static\IMAGENS_PRODUTOS\MESA LATERAL PD27_77526.jpg | C570: MESA LATERAL PD27 | D570: 77526
A571: 223615 | B571: \\192.168.0.4\Produtos\PRODUTO_PRONTA_ENTREGA\static\IMAGENS_PRODUTOS\MESA LATERAL PIQUE_223615.jpg | C571: MESA LATERAL PIQUE | D571: 223615
A572: 121068 | B572: \\192.168.0.4\Produtos\PRODUTO_PRONTA_ENTREGA\static\IMAGENS_PRODUTOS\MESA LATERAL PRIMAVERA_121068.jpg | C572: MESA LATERAL PRIMAVERA | D572: 121068
A573: 163886 | B573: \\192.168.0.4\Produtos\PRODUTO_PRONTA_ENTREGA\static\IMAGENS_PRODUTOS\MESA LATERAL SINCRO_163886.jpg | C573: MESA LATERAL SINCRO | D573: 163886
A574: 270487 | B574: \\192.168.0.4\Produtos\PRODUTO_PRONTA_ENTREGA\static\IMAGENS_PRODUTOS\MESA LATERAL SMITH_270487.jpg | C574: MESA LATERAL SMITH | D574: 270487
A575: 191034 | B575: \\192.168.0.4\Produtos\PRODUTO_PRONTA_ENTREGA\static\IMAGENS_PRODUTOS\MESA LATERAL STOOL_191034.jpg | C575: MESA LATERAL STOOL | D575: 191034
A576: 229324 | B576: \\192.168.0.4\Produtos\PRODUTO_PRONTA_ENTREGA\static\IMAGENS_PRODUTOS\MESA LATERAL SUN_229324.jpg | C576: MESA LATERAL SUN | D576: 229324
A577: 223568 | B577: \\192.168.0.4\Produtos\PRODUTO_PRONTA_ENTREGA\static\IMAGENS_PRODUTOS\MESA LATERAL TRIBO _223568.jpg | C577: MESA LATERAL TRIBO | D577: 223568
...
